Workbook

Sheet Quiz 1
A1: Student ID | B1: Name (if no ID) | C1: Question 1 | D1: Question 2 | E1: Question 3 | F1: Total / 3 | G1: Form | H1: Grade / 10 | I1: Course points / 0.75
A2: 200 | C2: 1 | D2: 1 | E2: 1 | F2: 3 | G2: UF5C | H2: =F2/3*10 -> 10 | I2: =H2*7.5% -> 0.75
A3: 201 | C3: 1 | D3: 1 | E3: 1 | F3: 3 | G3: P76Y | H3: =F3/3*10 -> 10 | I3: =H3*7.5% -> 0.75
A4: 202 | C4: 1 | D4: 1 | E4: 1 | F4: 3 | G4: UF5C | H4: =F4/3*10 -> 10 | I4: =H4*7.5% -> 0.75
A5: 203 | C5: 1 | D5: 1 | E5: 1 | F5: 3 | G5: PEY5 | H5: =F5/3*10 -> 10 | I5: =H5*7.5% -> 0.75
A6: 204 | C6: 1 | D6: 1 | E6: 1 | F6: 3 | G6: B7CS | H6: =F6/3*10 -> 10 | I6: =H6*7.5% -> 0.75
A7: 205 | C7: 1 | D7: 1 | E7: 1 | F7: 3 | G7: K7RX | H7: =F7/3*10 -> 10 | I7: =H7*7.5% -> 0.75
A8: 206 | C8: 0 | D8: 1 | E8: 1 | F8: 2 | G8: P76Y | H8: =F8/3*10 -> 6.6666667 | I8: =H8*7.5% -> 0.5
A9: 207 | C9: 1 | D9: 1 | E9: 1 | F9: 3 | G9: B7CS | H9: =F9/3*10 -> 10 | I9: =H9*7.5% -> 0.75
A10: 208 | C10: 1 | D10: 1 | E10: 1 | F10: 3 | G10: P76Y | H10: =F10/3*10 -> 10 | I10: =H10*7.5% -> 0.75
A11: 209 | C11: 1 | D11: 1 | E11: 0 | F11: 2 | G11: B7CS | H11: =F11/3*10 -> 6.6666667 | I11: =H11*7.5% -> 0.5
A12: 210 | C12: 1 | D12: 0 | E12: 1 | F12: 2 | G12: THZ2 | H12: =F12/3*10 -> 6.6666667 | I12: =H12*7.5% -> 0.5
A13: 211 | C13: 0 | D13: 1 | E13: 1 | F13: 2 | G13: P76Y | H13: =F13/3*10 -> 6.6666667 | I13: =H13*7.5% -> 0.5
... A38: 243 | C38: 0 | D38: 1 | E38: 0 | F38: 1 | G38: P76Y | H38: =F38/3*10 -> 3.3333333 | I38: =H38*7.5% -> 0.25
B39: LVL | C39: 0 | D39: 0 | E39: 0 | F39: 0 | G39: THZ2 | H39: =F39/3*10 -> 0 | I39: =H39*7.5% -> 0
B40: AMR | C40: 1 | D40: 0 | E40: 1 | F40: 2 | G40: UF5C | H40: =F40/3*10 -> 6.6666667 | I40: =H40*7.5% -> 0.5
B41: TS | C41: 0 | D41: 1 | E41: 0 | F41: 1 | G41: PEY5 | H41: =F41/3*10 -> 3.3333333 | I41: =H41*7.5% -> 0.25
B42: YML | C42: 0 | D42: 0 | E42: 0 | F42: 0 | G42: B7CS | H42: =F42/3*10 -> 0 | I42: =H42*7.5% -> 0
A45: Quiz 1: maximum 3 raw points. Grade / 10 = raw points ÷ 3 × 10. This quiz contributes 7.5% of the course grade, at most 0.75 course points.
A46: For the same quiz and student ID, the highest score across original and makeup attempts is retained.

Sheet Quiz 2
A1: Student ID | B1: Name (if no ID) | C1: Question 1 | D1: Question 2 | E1: Question 3 | F1: Total / 3 | G1: Form | H1: Grade / 10 | I1: Course points / 0.75
A2: 200 | C2: 1 | D2: 0 | E2: 1 | F2: 2 | G2: 8NDK | H2: =F2/3*10 -> 6.6666667 | I2: =H2*7.5% -> 0.5
A3: 201 | C3: 1 | D3: 1 | E3: 1 | F3: 3 | G3: N3VX | H3: =F3/3*10 -> 10 | I3: =H3*7.5% -> 0.75
A4: 202 | C4: 1 | D4: 1 | E4: 0 | F4: 2 | G4: TW3R | H4: =F4/3*10 -> 6.6666667 | I4: =H4*7.5% -> 0.5
A5: 203 | C5: 1 | D5: 1 | E5: 1 | F5: 3 | G5: J2WJ | H5: =F5/3*10 -> 10 | I5: =H5*7.5% -> 0.75
A6: 204 | C6: 1 | D6: 1 | E6: 1 | F6: 3 | G6: 8NDK | H6: =F6/3*10 -> 10 | I6: =H6*7.5% -> 0.75
A7: 206 | C7: 1 | D7: 1 | E7: 0 | F7: 2 | G7: J2WJ | H7: =F7/3*10 -> 6.6666667 | I7: =H7*7.5% -> 0.5
A8: 207 | C8: 1 | D8: 0 | E8: 1 | F8: 2 | G8: TW3R | H8: =F8/3*10 -> 6.6666667 | I8: =H8*7.5% -> 0.5
A9: 208 | C9: 1 | D9: 1 | E9: 0 | F9: 2 | G9: J2WJ | H9: =F9/3*10 -> 6.6666667 | I9: =H9*7.5% -> 0.5
A10: 209 | C10: 1 | D10: 1 | E10: 1 | F10: 3 | G10: TW3R | H10: =F10/3*10 -> 10 | I10: =H10*7.5% -> 0.75
A11: 210 | C11: 1 | D11: 0 | E11: 1 | F11: 2 | G11: TW3R | H11: =F11/3*10 -> 6.6666667 | I11: =H11*7.5% -> 0.5
A12: 211 | C12: 1 | D12: 0 | E12: 1 | F12: 2 | G12: EA3R | H12: =F12/3*10 -> 6.6666667 | I12: =H12*7.5% -> 0.5
A13: 212 | C13: 1 | D13: 1 | E13: 1 | F13: 3 | G13: TW3R | H13: =F13/3*10 -> 10 | I13: =H13*7.5% -> 0.75
... A37: 240 | C37: 1 | D37: 0 | E37: 1 | F37: 2 | G37: EA3R | H37: =F37/3*10 -> 6.6666667 | I37: =H37*7.5% -> 0.5
A40: Quiz 2: maximum 3 raw points. Grade / 10 = raw points ÷ 3 × 10. This quiz contributes 7.5% of the course grade, at most 0.75 course points.
A41: For the same quiz and student ID, the highest score across original and makeup attempts is retained.

Sheet Quiz 3
A1: Student ID | B1: Name (if no ID) | C1: Question 1 | D1: Question 2 | E1: Question 3 | F1: Total / 3 | G1: Form | H1: Grade / 10 | I1: Course points / 0.75
A2: 200 | C2: 1 | D2: 1 | E2: 1 | F2: 3 | G2: QKMC | H2: =F2/3*10 -> 10 | I2: =H2*7.5% -> 0.75
A3: 201 | C3: 1 | D3: 1 | E3: 0 | F3: 2 | G3: QYU7 | H3: =F3/3*10 -> 6.6666667 | I3: =H3*7.5% -> 0.5
A4: 202 | C4: 1 | D4: 1 | E4: 0 | F4: 2 | G4: QNLW | H4: =F4/3*10 -> 6.6666667 | I4: =H4*7.5% -> 0.5
A5: 203 | C5: 1 | D5: 1 | E5: 1 | F5: 3 | G5: QYU7 | H5: =F5/3*10 -> 10 | I5: =H5*7.5% -> 0.75
A6: 204 | C6: 1 | D6: 1 | E6: 1 | F6: 3 | G6: QNLW | H6: =F6/3*10 -> 10 | I6: =H6*7.5% -> 0.75
A7: 206 | C7: 0 | D7: 1 | E7: 1 | F7: 2 | G7: QJ2H | H7: =F7/3*10 -> 6.6666667 | I7: =H7*7.5% -> 0.5
A8: 207 | C8: 1 | D8: 1 | E8: 1 | F8: 3 | G8: QJ2H | H8: =F8/3*10 -> 10 | I8: =H8*7.5% -> 0.75
A9: 208 | C9: 0 | D9: 0 | E9: 0 | F9: 0 | G9: Q2UP | H9: =F9/3*10 -> 0 | I9: =H9*7.5% -> 0
A10: 209 | C10: 0 | D10: 1 | E10: 0 | F10: 1 | G10: Q2UP | H10: =F10/3*10 -> 3.3333333 | I10: =H10*7.5% -> 0.25
A11: 210 | C11: 1 | D11: 1 | E11: 1 | F11: 3 | G11: Q2UP | H11: =F11/3*10 -> 10 | I11: =H11*7.5% -> 0.75
A12: 211 | C12: 1 | D12: 1 | E12: 1 | F12: 3 | G12: QNLW | H12: =F12/3*10 -> 10 | I12: =H12*7.5% -> 0.75
A13: 212 | C13: 1 | D13: 1 | E13: 0 | F13: 2 | G13: QKMC | H13: =F13/3*10 -> 6.6666667 | I13: =H13*7.5% -> 0.5
... A35: 240 | C35: 0 | D35: 1 | E35: 0 | F35: 1 | G35: QNLW | H35: =F35/3*10 -> 3.3333333 | I35: =H35*7.5% -> 0.25
A38: Quiz 3: maximum 3 raw points. Grade / 10 = raw points ÷ 3 × 10. This quiz contributes 7.5% of the course grade, at most 0.75 course points.
A39: For the same quiz and student ID, the highest score across original and makeup attempts is retained.

Sheet Quiz 4
A1: Student ID | B1: Name (if no ID) | C1: Question 1 | D1: Question 2 | E1: Question 3 | F1: Total / 3 | G1: Form | H1: Grade / 10 | I1: Course points / 0.75
A2: 200 | C2: 1 | D2: 0 | E2: 1 | F2: 2 | G2: 4S6B | H2: =F2/3*10 -> 6.6666667 | I2: =H2*7.5% -> 0.5
A3: 201 | C3: 1 | D3: 0 | E3: 1 | F3: 2 | G3: 4GLW | H3: =F3/3*10 -> 6.6666667 | I3: =H3*7.5% -> 0.5
A4: 202 | C4: 0 | D4: 1 | E4: 1 | F4: 2 | G4: V6JP | H4: =F4/3*10 -> 6.6666667 | I4: =H4*7.5% -> 0.5
A5: 203 | C5: 1 | D5: 1 | E5: 1 | F5: 3 | G5: 4GLW | H5: =F5/3*10 -> 10 | I5: =H5*7.5% -> 0.75
A6: 204 | C6: 1 | D6: 0 | E6: 1 | F6: 2 | G6: 4HPW | H6: =F6/3*10 -> 6.6666667 | I6: =H6*7.5% -> 0.5
A7: 205 | C7: 1 | D7: 0 | E7: 1 | F7: 2 | G7: 4S6B | H7: =F7/3*10 -> 6.6666667 | I7: =H7*7.5% -> 0.5
A8: 206 | C8: 1 | D8: 1 | E8: 1 | F8: 3 | G8: V7HF | H8: =F8/3*10 -> 10 | I8: =H8*7.5% -> 0.75
A9: 207 | C9: 1 | D9: 1 | E9: 1 | F9: 3 | G9: 423M | H9: =F9/3*10 -> 10 | I9: =H9*7.5% -> 0.75
A10: 208 | C10: 1 | D10: 0 | E10: 1 | F10: 2 | G10: 4GLW | H10: =F10/3*10 -> 6.6666667 | I10: =H10*7.5% -> 0.5
A11: 209 | C11: 1 | D11: 1 | E11: 0 | F11: 2 | G11: 4H8M | H11: =F11/3*10 -> 6.6666667 | I11: =H11*7.5% -> 0.5
A12: 210 | C12: 0 | D12: 1 | E12: 1 | F12: 2 | G12: 4S6B | H12: =F12/3*10 -> 6.6666667 | I12: =H12*7.5% -> 0.5
A13: 211 | C13: 1 | D13: 0 | E13: 1 | F13: 2 | G13: 4HPW | H13: =F13/3*10 -> 6.6666667 | I13: =H13*7.5% -> 0.5
... A37: 240 | C37: 0 | D37: 0 | E37: 0 | F37: 0 | G37: 4S6B | H37: =F37/3*10 -> 0 | I37: =H37*7.5% -> 0
A40: Quiz 4: maximum 3 raw points. Grade / 10 = raw points ÷ 3 × 10. This quiz contributes 7.5% of the course grade, at most 0.75 course points.
A41: For the same quiz and student ID, the highest score across original and makeup attempts is retained.

Sheet Midterm
A1: Student ID | B1: Raw points / 20 | C1: Grade / 10 | D1: Course points / 2 | E1: Form
A2: 200 | B2: 15 | C2: =B2/20*10 -> 7.5 | D2: =C2*20% -> 1.5 | E2: M7KD
A3: 201 | B3: 14 | C3: =B3/20*10 -> 7 | D3: =C3*20% -> 1.4 | E3: M6WP
A4: 202 | B4: 19 | C4: =B4/20*10 -> 9.5 | D4: =C4*20% -> 1.9 | E4: M6WP
A5: 203 | B5: 17 | C5: =B5/20*10 -> 8.5 | D5: =C5*20% -> 1.7 | E5: M2HF
A6: 204 | B6: 19 | C6: =B6/20*10 -> 9.5 | D6: =C6*20% -> 1.9 | E6: M8VN
A7: 205 | B7: 16 | C7: =B7/20*10 -> 8 | D7: =C7*20% -> 1.6 | E7: M3RX
A8: 206 | B8: 16 | C8: =B8/20*10 -> 8 | D8: =C8*20% -> 1.6 | E8: M6WP
A9: 207 | B9: 16 | C9: =B9/20*10 -> 8 | D9: =C9*20% -> 1.6 | E9: M7KD
A10: 208 | B10: 13 | C10: =B10/20*10 -> 6.5 | D10: =C10*20% -> 1.3 | E10: M7KD
A11: 209 | B11: 11 | C11: =B11/20*10 -> 5.5 | D11: =C11*20% -> 1.1 | E11: M6WP
A12: 210 | B12: 17 | C12: =B12/20*10 -> 8.5 | D12: =C12*20% -> 1.7 | E12: M2HF
A13: 211 | B13: 15 | C13: =B13/20*10 -> 7.5 | D13: =C13*20% -> 1.5 | E13: M6WP
... A40: 240 | B40: 6 | C40: =B40/20*10 -> 3 | D40: =C40*20% -> 0.6 | E40: M2HF
A43: Midterm: one point per correct answer; incorrect, blank and unresolved multiple answers score zero. Maximum 20 raw points.
A44: Grade / 10 = raw points ÷ 20 × 10. The midterm contributes 20% of the course grade, at most 2 course points.

Sheet Overall Grade
A1: Student ID | B1: Quiz 1 / 10 | C1: Quiz 2 / 10 | D1: Quiz 3 / 10 | E1: Quiz 4 / 10 | F1: Midterm / 10 | G1: Quizzes: course points / 3 | H1: Midterm: course points / 2 | I1: Swapnil: course points / 5 | J1: Swapnil: normalized grade / 10 | K1: Other instructor: grade / 10 | L1: Final course grade / 10 | M1: Record status
A2: 200 | B2: =_xlfn.MAXIFS('Quiz 1'!$H$2:$H$42,'Quiz 1'!$A$2:$A$42,$A2) -> 10 | C2: =_xlfn.MAXIFS('Quiz 2'!$H$2:$H$37,'Quiz 2'!$A$2:$A$37,$A2) -> 6.6666667 | D2: =_xlfn.MAXIFS('Quiz 3'!$H$2:$H$35,'Quiz 3'!$A$2:$A$35,$A2) -> 10 | E2: =_xlfn.MAXIFS('Quiz 4'!$H$2:$H$37,'Quiz 4'!$A$2:$A$37,$A2) -> 6.6666667 | F2: =SUMIF(Midterm!$A$2:$A$40,$A2,Midterm!$C$2:$C$40) -> 7.5 | G2: =SUM(B2:E2)*7.5% -> 2.5 | H2: =F2*20% -> 1.5 | I2: =G2+H2 -> 4 | J2: =I2/50% -> 8 | L2: =IF(ISNUMBER(K2),I2+K2*50%,"") | M2: =IF(ISNUMBER(K2),"Complete","Other instructor pending")&"" -> Other instructor pending
A3: 201 | B3: =_xlfn.MAXIFS('Quiz 1'!$H$2:$H$42,'Quiz 1'!$A$2:$A$42,$A3) -> 10 | C3: =_xlfn.MAXIFS('Quiz 2'!$H$2:$H$37,'Quiz 2'!$A$2:$A$37,$A3) -> 10 | D3: =_xlfn.MAXIFS('Quiz 3'!$H$2:$H$35,'Quiz 3'!$A$2:$A$35,$A3) -> 6.6666667 | E3: =_xlfn.MAXIFS('Quiz 4'!$H$2:$H$37,'Quiz 4'!$A$2:$A$37,$A3) -> 6.6666667 | F3: =SUMIF(Midterm!$A$2:$A$40,$A3,Midterm!$C$2:$C$40) -> 7 | G3: =SUM(B3:E3)*7.5% -> 2.5 | H3: =F3*20% -> 1.4 | I3: =G3+H3 -> 3.9 | J3: =I3/50% -> 7.8 | L3: =IF(ISNUMBER(K3),I3+K3*50%,"") | M3: =IF(ISNUMBER(K3),"Complete","Other instructor pending")&"" -> Other instructor pending
A4: 202 | B4: =_xlfn.MAXIFS('Quiz 1'!$H$2:$H$42,'Quiz 1'!$A$2:$A$42,$A4) -> 10 | C4: =_xlfn.MAXIFS('Quiz 2'!$H$2:$H$37,'Quiz 2'!$A$2:$A$37,$A4) -> 6.6666667 | D4: =_xlfn.MAXIFS('Quiz 3'!$H$2:$H$35,'Quiz 3'!$A$2:$A$35,$A4) -> 6.6666667 | E4: =_xlfn.MAXIFS('Quiz 4'!$H$2:$H$37,'Quiz 4'!$A$2:$A$37,$A4) -> 6.6666667 | F4: =SUMIF(Midterm!$A$2:$A$40,$A4,Midterm!$C$2:$C$40) -> 9.5 | G4: =SUM(B4:E4)*7.5% -> 2.25 | H4: =F4*20% -> 1.9 | I4: =G4+H4 -> 4.15 | J4: =I4/50% -> 8.3 | L4: =IF(ISNUMBER(K4),I4+K4*50%,"") | M4: =IF(ISNUMBER(K4),"Complete","Other instructor pending")&"" -> Other instructor pending
A5: 203 | B5: =_xlfn.MAXIFS('Quiz 1'!$H$2:$H$42,'Quiz 1'!$A$2:$A$42,$A5) -> 10 | C5: =_xlfn.MAXIFS('Quiz 2'!$H$2:$H$37,'Quiz 2'!$A$2:$A$37,$A5) -> 10 | D5: =_xlfn.MAXIFS('Quiz 3'!$H$2:$H$35,'Quiz 3'!$A$2:$A$35,$A5) -> 10 | E5: =_xlfn.MAXIFS('Quiz 4'!$H$2:$H$37,'Quiz 4'!$A$2:$A$37,$A5) -> 10 | F5: =SUMIF(Midterm!$A$2:$A$40,$A5,Midterm!$C$2:$C$40) -> 8.5 | G5: =SUM(B5:E5)*7.5% -> 3 | H5: =F5*20% -> 1.7 | I5: =G5+H5 -> 4.7 | J5: =I5/50% -> 9.4 | L5: =IF(ISNUMBER(K5),I5+K5*50%,"") | M5: =IF(ISNUMBER(K5),"Complete","Other instructor pending")&"" -> Other instructor pending
A6: 204 | B6: =_xlfn.MAXIFS('Quiz 1'!$H$2:$H$42,'Quiz 1'!$A$2:$A$42,$A6) -> 10 | C6: =_xlfn.MAXIFS('Quiz 2'!$H$2:$H$37,'Quiz 2'!$A$2:$A$37,$A6) -> 10 | D6: =_xlfn.MAXIFS('Quiz 3'!$H$2:$H$35,'Quiz 3'!$A$2:$A$35,$A6) -> 10 | E6: =_xlfn.MAXIFS('Quiz 4'!$H$2:$H$37,'Quiz 4'!$A$2:$A$37,$A6) -> 6.6666667 | F6: =SUMIF(Midterm!$A$2:$A$40,$A6,Midterm!$C$2:$C$40) -> 9.5 | G6: =SUM(B6:E6)*7.5% -> 2.75 | H6: =F6*20% -> 1.9 | I6: =G6+H6 -> 4.65 | J6: =I6/50% -> 9.3 | L6: =IF(ISNUMBER(K6),I6+K6*50%,"") | M6: =IF(ISNUMBER(K6),"Complete","Other instructor pending")&"" -> Other instructor pending
A7: 205 | B7: =_xlfn.MAXIFS('Quiz 1'!$H$2:$H$42,'Quiz 1'!$A$2:$A$42,$A7) -> 10 | C7: =_xlfn.MAXIFS('Quiz 2'!$H$2:$H$37,'Quiz 2'!$A$2:$A$37,$A7) -> 0 | D7: =_xlfn.MAXIFS('Quiz 3'!$H$2:$H$35,'Quiz 3'!$A$2:$A$35,$A7) -> 0 | E7: =_xlfn.MAXIFS('Quiz 4'!$H$2:$H$37,'Quiz 4'!$A$2:$A$37,$A7) -> 6.6666667 | F7: =SUMIF(Midterm!$A$2:$A$40,$A7,Midterm!$C$2:$C$40) -> 8 | G7: =SUM(B7:E7)*7.5% -> 1.25 | H7: =F7*20% -> 1.6 | I7: =G7+H7 -> 2.85 | J7: =I7/50% -> 5.7 | L7: =IF(ISNUMBER(K7),I7+K7*50%,"") | M7: =IF(ISNUMBER(K7),"Complete","Other instructor pending")&"; no record: Quiz 2, Quiz 3" -> Other instructor pending; no record: Quiz 2, Quiz 3
A8: 206 | B8: =_xlfn.MAXIFS('Quiz 1'!$H$2:$H$42,'Quiz 1'!$A$2:$A$42,$A8) -> 6.6666667 | C8: =_xlfn.MAXIFS('Quiz 2'!$H$2:$H$37,'Quiz 2'!$A$2:$A$37,$A8) -> 6.6666667 | D8: =_xlfn.MAXIFS('Quiz 3'!$H$2:$H$35,'Quiz 3'!$A$2:$A$35,$A8) -> 6.6666667 | E8: =_xlfn.MAXIFS('Quiz 4'!$H$2:$H$37,'Quiz 4'!$A$2:$A$37,$A8) -> 10 | F8: =SUMIF(Midterm!$A$2:$A$40,$A8,Midterm!$C$2:$C$40) -> 8 | G8: =SUM(B8:E8)*7.5% -> 2.25 | H8: =F8*20% -> 1.6 | I8: =G8+H8 -> 3.85 | J8: =I8/50% -> 7.7 | L8: =IF(ISNUMBER(K8),I8+K8*50%,"") | M8: =IF(ISNUMBER(K8),"Complete","Other instructor pending")&"" -> Other instructor pending
A9: 207 | B9: =_xlfn.MAXIFS('Quiz 1'!$H$2:$H$42,'Quiz 1'!$A$2:$A$42,$A9) -> 10 | C9: =_xlfn.MAXIFS('Quiz 2'!$H$2:$H$37,'Quiz 2'!$A$2:$A$37,$A9) -> 6.6666667 | D9: =_xlfn.MAXIFS('Quiz 3'!$H$2:$H$35,'Quiz 3'!$A$2:$A$35,$A9) -> 10 | E9: =_xlfn.MAXIFS('Quiz 4'!$H$2:$H$37,'Quiz 4'!$A$2:$A$37,$A9) -> 10 | F9: =SUMIF(Midterm!$A$2:$A$40,$A9,Midterm!$C$2:$C$40) -> 8 | G9: =SUM(B9:E9)*7.5% -> 2.75 | H9: =F9*20% -> 1.6 | I9: =G9+H9 -> 4.35 | J9: =I9/50% -> 8.7 | L9: =IF(ISNUMBER(K9),I9+K9*50%,"") | M9: =IF(ISNUMBER(K9),"Complete","Other instructor pending")&"" -> Other instructor pending
A10: 208 | B10: =_xlfn.MAXIFS('Quiz 1'!$H$2:$H$42,'Quiz 1'!$A$2:$A$42,$A10) -> 10 | C10: =_xlfn.MAXIFS('Quiz 2'!$H$2:$H$37,'Quiz 2'!$A$2:$A$37,$A10) -> 6.6666667 | D10: =_xlfn.MAXIFS('Quiz 3'!$H$2:$H$35,'Quiz 3'!$A$2:$A$35,$A10) -> 0 | E10: =_xlfn.MAXIFS('Quiz 4'!$H$2:$H$37,'Quiz 4'!$A$2:$A$37,$A10) -> 6.6666667 | F10: =SUMIF(Midterm!$A$2:$A$40,$A10,Midterm!$C$2:$C$40) -> 6.5 | G10: =SUM(B10:E10)*7.5% -> 1.75 | H10: =F10*20% -> 1.3 | I10: =G10+H10 -> 3.05 | J10: =I10/50% -> 6.1 | L10: =IF(ISNUMBER(K10),I10+K10*50%,"") | M10: =IF(ISNUMBER(K10),"Complete","Other instructor pending")&"" -> Other instructor pending
A11: 209 | B11: =_xlfn.MAXIFS('Quiz 1'!$H$2:$H$42,'Quiz 1'!$A$2:$A$42,$A11) -> 6.6666667 | C11: =_xlfn.MAXIFS('Quiz 2'!$H$2:$H$37,'Quiz 2'!$A$2:$A$37,$A11) -> 10 | D11: =_xlfn.MAXIFS('Quiz 3'!$H$2:$H$35,'Quiz 3'!$A$2:$A$35,$A11) -> 3.3333333 | E11: =_xlfn.MAXIFS('Quiz 4'!$H$2:$H$37,'Quiz 4'!$A$2:$A$37,$A11) -> 6.6666667 | F11: =SUMIF(Midterm!$A$2:$A$40,$A11,Midterm!$C$2:$C$40) -> 5.5 | G11: =SUM(B11:E11)*7.5% -> 2 | H11: =F11*20% -> 1.1 | I11: =G11+H11 -> 3.1 | J11: =I11/50% -> 6.2 | L11: =IF(ISNUMBER(K11),I11+K11*50%,"") | M11: =IF(ISNUMBER(K11),"Complete","Other instructor pending")&"" -> Other instructor pending
A12: 210 | B12: =_xlfn.MAXIFS('Quiz 1'!$H$2:$H$42,'Quiz 1'!$A$2:$A$42,$A12) -> 6.6666667 | C12: =_xlfn.MAXIFS('Quiz 2'!$H$2:$H$37,'Quiz 2'!$A$2:$A$37,$A12) -> 6.6666667 | D12: =_xlfn.MAXIFS('Quiz 3'!$H$2:$H$35,'Quiz 3'!$A$2:$A$35,$A12) -> 10 | E12: =_xlfn.MAXIFS('Quiz 4'!$H$2:$H$37,'Quiz 4'!$A$2:$A$37,$A12) -> 6.6666667 | F12: =SUMIF(Midterm!$A$2:$A$40,$A12,Midterm!$C$2:$C$40) -> 8.5 | G12: =SUM(B12:E12)*7.5% -> 2.25 | H12: =F12*20% -> 1.7 | I12: =G12+H12 -> 3.95 | J12: =I12/50% -> 7.9 | L12: =IF(ISNUMBER(K12),I12+K12*50%,"") | M12: =IF(ISNUMBER(K12),"Complete","Other instructor pending")&"" -> Other instructor pending
A13: 211 | B13: =_xlfn.MAXIFS('Quiz 1'!$H$2:$H$42,'Quiz 1'!$A$2:$A$42,$A13) -> 6.6666667 | C13: =_xlfn.MAXIFS('Quiz 2'!$H$2:$H$37,'Quiz 2'!$A$2:$A$37,$A13) -> 6.6666667 | D13: =_xlfn.MAXIFS('Quiz 3'!$H$2:$H$35,'Quiz 3'!$A$2:$A$35,$A13) -> 10 | E13: =_xlfn.MAXIFS('Quiz 4'!$H$2:$H$37,'Quiz 4'!$A$2:$A$37,$A13) -> 6.6666667 | F13: =SUMIF(Midterm!$A$2:$A$40,$A13,Midterm!$C$2:$C$40) -> 7.5 | G13: =SUM(B13:E13)*7.5% -> 2.25 | H13: =F13*20% -> 1.5 | I13: =G13+H13 -> 3.75 | J13: =I13/50% -> 7.5 | L13: =IF(ISNUMBER(K13),I13+K13*50%,"") | M13: =IF(ISNUMBER(K13),"Complete","Other instructor pending")&"" -> Other instructor pending
A14: 212 | B14: =_xlfn.MAXIFS('Quiz 1'!$H$2:$H$42,'Quiz 1'!$A$2:$A$42,$A14) -> 6.6666667 | C14: =_xlfn.MAXIFS('Quiz 2'!$H$2:$H$37,'Quiz 2'!$A$2:$A$37,$A14) -> 10 | D14: =_xlfn.MAXIFS('Quiz 3'!$H$2:$H$35,'Quiz 3'!$A$2:$A$35,$A14) -> 6.6666667 | E14: =_xlfn.MAXIFS('Quiz 4'!$H$2:$H$37,'Quiz 4'!$A$2:$A$37,$A14) -> 6.6666667 | F14: =SUMIF(Midterm!$A$2:$A$40,$A14,Midterm!$C$2:$C$40) -> 7.5 | G14: =SUM(B14:E14)*7.5% -> 2.25 | H14: =F14*20% -> 1.5 | I14: =G14+H14 -> 3.75 | J14: =I14/50% -> 7.5 | L14: =IF(ISNUMBER(K14),I14+K14*50%,"") | M14: =IF(ISNUMBER(K14),"Complete","Other instructor pending")&"" -> Other instructor pending
A15: 213 | B15: =_xlfn.MAXIFS('Quiz 1'!$H$2:$H$42,'Quiz 1'!$A$2:$A$42,$A15) -> 3.3333333 | C15: =_xlfn.MAXIFS('Quiz 2'!$H$2:$H$37,'Quiz 2'!$A$2:$A$37,$A15) -> 3.3333333 | D15: =_xlfn.MAXIFS('Quiz 3'!$H$2:$H$35,'Quiz 3'!$A$2:$A$35,$A15) -> 3.3333333 | E15: =_xlfn.MAXIFS('Quiz 4'!$H$2:$H$37,'Quiz 4'!$A$2:$A$37,$A15) -> 3.3333333 | F15: =SUMIF(Midterm!$A$2:$A$40,$A15,Midterm!$C$2:$C$40) -> 6.5 | G15: =SUM(B15:E15)*7.5% -> 1 | H15: =F15*20% -> 1.3 | I15: =G15+H15 -> 2.3 | J15: =I15/50% -> 4.6 | L15: =IF(ISNUMBER(K15),I15+K15*50%,"") | M15: =IF(ISNUMBER(K15),"Complete","Other instructor pending")&"" -> Other instructor pending
A16: 214 | B16: =_xlfn.MAXIFS('Quiz 1'!$H$2:$H$42,'Quiz 1'!$A$2:$A$42,$A16) -> 10 | C16: =_xlfn.MAXIFS('Quiz 2'!$H$2:$H$37,'Quiz 2'!$A$2:$A$37,$A16) -> 10 | D16: =_xlfn.MAXIFS('Quiz 3'!$H$2:$H$35,'Quiz 3'!$A$2:$A$35,$A16) -> 10 | E16: =_xlfn.MAXIFS('Quiz 4'!$H$2:$H$37,'Quiz 4'!$A$2:$A$37,$A16) -> 10 | F16: =SUMIF(Midterm!$A$2:$A$40,$A16,Midterm!$C$2:$C$40) -> 10 | G16: =SUM(B16:E16)*7.5% -> 3 | H16: =F16*20% -> 2 | I16: =G16+H16 -> 5 | J16: =I16/50% -> 10 | L16: =IF(ISNUMBER(K16),I16+K16*50%,"") | M16: =IF(ISNUMBER(K16),"Complete","Other instructor pending")&"" -> Other instructor pending
A17: 215 | B17: =_xlfn.MAXIFS('Quiz 1'!$H$2:$H$42,'Quiz 1'!$A$2:$A$42,$A17) -> 6.6666667 | C17: =_xlfn.MAXIFS('Quiz 2'!$H$2:$H$37,'Quiz 2'!$A$2:$A$37,$A17) -> 6.6666667 | D17: =_xlfn.MAXIFS('Quiz 3'!$H$2:$H$35,'Quiz 3'!$A$2:$A$35,$A17) -> 10 | E17: =_xlfn.MAXIFS('Quiz 4'!$H$2:$H$37,'Quiz 4'!$A$2:$A$37,$A17) -> 6.6666667 | F17: =SUMIF(Midterm!$A$2:$A$40,$A17,Midterm!$C$2:$C$40) -> 8 | G17: =SUM(B17:E17)*7.5% -> 2.25 | H17: =F17*20% -> 1.6 | I17: =G17+H17 -> 3.85 | J17: =I17/50% -> 7.7 | L17: =IF(ISNUMBER(K17),I17+K17*50%,"") | M17: =IF(ISNUMBER(K17),"Complete","Other instructor pending")&"" -> Other instructor pending
A18: 216 | B18: =_xlfn.MAXIFS('Quiz 1'!$H$2:$H$42,'Quiz 1'!$A$2:$A$42,$A18) -> 10 | C18: =_xlfn.MAXIFS('Quiz 2'!$H$2:$H$37,'Quiz 2'!$A$2:$A$37,$A18) -> 3.3333333 | D18: =_xlfn.MAXIFS('Quiz 3'!$H$2:$H$35,'Quiz 3'!$A$2:$A$35,$A18) -> 6.6666667 | E18: =_xlfn.MAXIFS('Quiz 4'!$H$2:$H$37,'Quiz 4'!$A$2:$A$37,$A18) -> 0 | F18: =SUMIF(Midterm!$A$2:$A$40,$A18,Midterm!$C$2:$C$40) -> 6 | G18: =SUM(B18:E18)*7.5% -> 1.5 | H18: =F18*20% -> 1.2 | I18: =G18+H18 -> 2.7 | J18: =I18/50% -> 5.4 | L18: =IF(ISNUMBER(K18),I18+K18*50%,"") | M18: =IF(ISNUMBER(K18),"Complete","Other instructor pending")&"; no record: Quiz 4" -> Other instructor pending; no record: Quiz 4
A19: 217 | B19: =_xlfn.MAXIFS('Quiz 1'!$H$2:$H$42,'Quiz 1'!$A$2:$A$42,$A19) -> 10 | C19: =_xlfn.MAXIFS('Quiz 2'!$H$2:$H$37,'Quiz 2'!$A$2:$A$37,$A19) -> 6.6666667 | D19: =_xlfn.MAXIFS('Quiz 3'!$H$2:$H$35,'Quiz 3'!$A$2:$A$35,$A19) -> 10 | E19: =_xlfn.MAXIFS('Quiz 4'!$H$2:$H$37,'Quiz 4'!$A$2:$A$37,$A19) -> 6.6666667 | F19: =SUMIF(Midterm!$A$2:$A$40,$A19,Midterm!$C$2:$C$40) -> 8 | G19: =SUM(B19:E19)*7.5% -> 2.5 | H19: =F19*20% -> 1.6 | I19: =G19+H19 -> 4.1 | J19: =I19/50% -> 8.2 | L19: =IF(ISNUMBER(K19),I19+K19*50%,"") | M19: =IF(ISNUMBER(K19),"Complete","Other instructor pending")&"" -> Other instructor pending
A20: 219 | B20: =_xlfn.MAXIFS('Quiz 1'!$H$2:$H$42,'Quiz 1'!$A$2:$A$42,$A20) -> 10 | C20: =_xlfn.MAXIFS('Quiz 2'!$H$2:$H$37,'Quiz 2'!$A$2:$A$37,$A20) -> 6.6666667 | D20: =_xlfn.MAXIFS('Quiz 3'!$H$2:$H$35,'Quiz 3'!$A$2:$A$35,$A20) -> 6.6666667 | E20: =_xlfn.MAXIFS('Quiz 4'!$H$2:$H$37,'Quiz 4'!$A$2:$A$37,$A20) -> 6.6666667 | F20: =SUMIF(Midterm!$A$2:$A$40,$A20,Midterm!$C$2:$C$40) -> 6 | G20: =SUM(B20:E20)*7.5% -> 2.25 | H20: =F20*20% -> 1.2 | I20: =G20+H20 -> 3.45 | J20: =I20/50% -> 6.9 | L20: =IF(ISNUMBER(K20),I20+K20*50%,"") | M20: =IF(ISNUMBER(K20),"Complete","Other instructor pending")&"" -> Other instructor pending
A21: 220 | B21: =_xlfn.MAXIFS('Quiz 1'!$H$2:$H$42,'Quiz 1'!$A$2:$A$42,$A21) -> 0 | C21: =_xlfn.MAXIFS('Quiz 2'!$H$2:$H$37,'Quiz 2'!$A$2:$A$37,$A21) -> 0 | D21: =_xlfn.MAXIFS('Quiz 3'!$H$2:$H$35,'Quiz 3'!$A$2:$A$35,$A21) -> 0 | E21: =_xlfn.MAXIFS('Quiz 4'!$H$2:$H$37,'Quiz 4'!$A$2:$A$37,$A21) -> 0 | F21: =SUMIF(Midterm!$A$2:$A$40,$A21,Midterm!$C$2:$C$40) -> 3.5 | G21: =SUM(B21:E21)*7.5% -> 0 | H21: =F21*20% -> 0.7 | I21: =G21+H21 -> 0.7 | J21: =I21/50% -> 1.4 | L21: =IF(ISNUMBER(K21),I21+K21*50%,"") | M21: =IF(ISNUMBER(K21),"Complete","Other instructor pending")&"; no record: Quiz 1, Quiz 2, Quiz 3, Quiz 4" -> Other instructor pending; no record: Quiz 1, Quiz 2, Quiz 3, Quiz 4
A22: 221 | B22: =_xlfn.MAXIFS('Quiz 1'!$H$2:$H$42,'Quiz 1'!$A$2:$A$42,$A22) -> 10 | C22: =_xlfn.MAXIFS('Quiz 2'!$H$2:$H$37,'Quiz 2'!$A$2:$A$37,$A22) -> 10 | D22: =_xlfn.MAXIFS('Quiz 3'!$H$2:$H$35,'Quiz 3'!$A$2:$A$35,$A22) -> 10 | E22: =_xlfn.MAXIFS('Quiz 4'!$H$2:$H$37,'Quiz 4'!$A$2:$A$37,$A22) -> 6.6666667 | F22: =SUMIF(Midterm!$A$2:$A$40,$A22,Midterm!$C$2:$C$40) -> 9.5 | G22: =SUM(B22:E22)*7.5% -> 2.75 | H22: =F22*20% -> 1.9 | I22: =G22+H22 -> 4.65 | J22: =I22/50% -> 9.3 | L22: =IF(ISNUMBER(K22),I22+K22*50%,"") | M22: =IF(ISNUMBER(K22),"Complete","Other instructor pending")&"" -> Other instructor pending
A23: 222 | B23: =_xlfn.MAXIFS('Quiz 1'!$H$2:$H$42,'Quiz 1'!$A$2:$A$42,$A23) -> 10 | C23: =_xlfn.MAXIFS('Quiz 2'!$H$2:$H$37,'Quiz 2'!$A$2:$A$37,$A23) -> 6.6666667 | D23: =_xlfn.MAXIFS('Quiz 3'!$H$2:$H$35,'Quiz 3'!$A$2:$A$35,$A23) -> 0 | E23: =_xlfn.MAXIFS('Quiz 4'!$H$2:$H$37,'Quiz 4'!$A$2:$A$37,$A23) -> 10 | F23: =SUMIF(Midterm!$A$2:$A$40,$A23,Midterm!$C$2:$C$40) -> 1 | G23: =SUM(B23:E23)*7.5% -> 2 | H23: =F23*20% -> 0.2 | I23: =G23+H23 -> 2.2 | J23: =I23/50% -> 4.4 | L23: =IF(ISNUMBER(K23),I23+K23*50%,"") | M23: =IF(ISNUMBER(K23),"Complete","Other instructor pending")&"; no record: Quiz 3" -> Other instructor pending; no record: Quiz 3
A24: 223 | B24: =_xlfn.MAXIFS('Quiz 1'!$H$2:$H$42,'Quiz 1'!$A$2:$A$42,$A24) -> 10 | C24: =_xlfn.MAXIFS('Quiz 2'!$H$2:$H$37,'Quiz 2'!$A$2:$A$37,$A24) -> 6.6666667 | D24: =_xlfn.MAXIFS('Quiz 3'!$H$2:$H$35,'Quiz 3'!$A$2:$A$35,$A24) -> 10 | E24: =_xlfn.MAXIFS('Quiz 4'!$H$2:$H$37,'Quiz 4'!$A$2:$A$37,$A24) -> 6.6666667 | F24: =SUMIF(Midterm!$A$2:$A$40,$A24,Midterm!$C$2:$C$40) -> 8 | G24: =SUM(B24:E24)*7.5% -> 2.5 | H24: =F24*20% -> 1.6 | I24: =G24+H24 -> 4.1 | J24: =I24/50% -> 8.2 | L24: =IF(ISNUMBER(K24),I24+K24*50%,"") | M24: =IF(ISNUMBER(K24),"Complete","Other instructor pending")&"" -> Other instructor pending
A25: 224 | B25: =_xlfn.MAXIFS('Quiz 1'!$H$2:$H$42,'Quiz 1'!$A$2:$A$42,$A25) -> 10 | C25: =_xlfn.MAXIFS('Quiz 2'!$H$2:$H$37,'Quiz 2'!$A$2:$A$37,$A25) -> 6.6666667 | D25: =_xlfn.MAXIFS('Quiz 3'!$H$2:$H$35,'Quiz 3'!$A$2:$A$35,$A25) -> 3.3333333 | E25: =_xlfn.MAXIFS('Quiz 4'!$H$2:$H$37,'Quiz 4'!$A$2:$A$37,$A25) -> 6.6666667 | F25: =SUMIF(Midterm!$A$2:$A$40,$A25,Midterm!$C$2:$C$40) -> 8 | G25: =SUM(B25:E25)*7.5% -> 2 | H25: =F25*20% -> 1.6 | I25: =G25+H25 -> 3.6 | J25: =I25/50% -> 7.2 | L25: =IF(ISNUMBER(K25),I25+K25*50%,"") | M25: =IF(ISNUMBER(K25),"Complete","Other instructor pending")&"" -> Other instructor pending
A26: 225 | B26: =_xlfn.MAXIFS('Quiz 1'!$H$2:$H$42,'Quiz 1'!$A$2:$A$42,$A26) -> 10 | C26: =_xlfn.MAXIFS('Quiz 2'!$H$2:$H$37,'Quiz 2'!$A$2:$A$37,$A26) -> 10 | D26: =_xlfn.MAXIFS('Quiz 3'!$H$2:$H$35,'Quiz 3'!$A$2:$A$35,$A26) -> 6.6666667 | E26: =_xlfn.MAXIFS('Quiz 4'!$H$2:$H$37,'Quiz 4'!$A$2:$A$37,$A26) -> 6.6666667 | F26: =SUMIF(Midterm!$A$2:$A$40,$A26,Midterm!$C$2:$C$40) -> 9.5 | G26: =SUM(B26:E26)*7.5% -> 2.5 | H26: =F26*20% -> 1.9 | I26: =G26+H26 -> 4.4 | J26: =I26/50% -> 8.8 | L26: =IF(ISNUMBER(K26),I26+K26*50%,"") | M26: =IF(ISNUMBER(K26),"Complete","Other instructor pending")&"" -> Other instructor pending
A27: 226 | B27: =_xlfn.MAXIFS('Quiz 1'!$H$2:$H$42,'Quiz 1'!$A$2:$A$42,$A27) -> 10 | C27: =_xlfn.MAXIFS('Quiz 2'!$H$2:$H$37,'Quiz 2'!$A$2:$A$37,$A27) -> 10 | D27: =_xlfn.MAXIFS('Quiz 3'!$H$2:$H$35,'Quiz 3'!$A$2:$A$35,$A27) -> 6.6666667 | E27: =_xlfn.MAXIFS('Quiz 4'!$H$2:$H$37,'Quiz 4'!$A$2:$A$37,$A27) -> 10 | F27: =SUMIF(Midterm!$A$2:$A$40,$A27,Midterm!$C$2:$C$40) -> 8 | G27: =SUM(B27:E27)*7.5% -> 2.75 | H27: =F27*20% -> 1.6 | I27: =G27+H27 -> 4.35 | J27: =I27/50% -> 8.7 | L27: =IF(ISNUMBER(K27),I27+K27*50%,"") | M27: =IF(ISNUMBER(K27),"Complete","Other instructor pending")&"" -> Other instructor pending
A28: 227 | B28: =_xlfn.MAXIFS('Quiz 1'!$H$2:$H$42,'Quiz 1'!$A$2:$A$42,$A28) -> 6.6666667 | C28: =_xlfn.MAXIFS('Quiz 2'!$H$2:$H$37,'Quiz 2'!$A$2:$A$37,$A28) -> 3.3333333 | D28: =_xlfn.MAXIFS('Quiz 3'!$H$2:$H$35,'Quiz 3'!$A$2:$A$35,$A28) -> 10 | E28: =_xlfn.MAXIFS('Quiz 4'!$H$2:$H$37,'Quiz 4'!$A$2:$A$37,$A28) -> 0 | F28: =SUMIF(Midterm!$A$2:$A$40,$A28,Midterm!$C$2:$C$40) -> 5 | G28: =SUM(B28:E28)*7.5% -> 1.5 | H28: =F28*20% -> 1 | I28: =G28+H28 -> 2.5 | J28: =I28/50% -> 5 | L28: =IF(ISNUMBER(K28),I28+K28*50%,"") | M28: =IF(ISNUMBER(K28),"Complete","Other instructor pending")&"" -> Other instructor pending
A29: 228 | B29: =_xlfn.MAXIFS('Quiz 1'!$H$2:$H$42,'Quiz 1'!$A$2:$A$42,$A29) -> 10 | C29: =_xlfn.MAXIFS('Quiz 2'!$H$2:$H$37,'Quiz 2'!$A$2:$A$37,$A29) -> 10 | D29: =_xlfn.MAXIFS('Quiz 3'!$H$2:$H$35,'Quiz 3'!$A$2:$A$35,$A29) -> 3.3333333 | E29: =_xlfn.MAXIFS('Quiz 4'!$H$2:$H$37,'Quiz 4'!$A$2:$A$37,$A29) -> 6.6666667 | F29: =SUMIF(Midterm!$A$2:$A$40,$A29,Midterm!$C$2:$C$40) -> 5.5 | G29: =SUM(B29:E29)*7.5% -> 2.25 | H29: =F29*20% -> 1.1 | I29: =G29+H29 -> 3.35 | J29: =I29/50% -> 6.7 | L29: =IF(ISNUMBER(K29),I29+K29*50%,"") | M29: =IF(ISNUMBER(K29),"Complete","Other instructor pending")&"" -> Other instructor pending
A30: 229 | B30: =_xlfn.MAXIFS('Quiz 1'!$H$2:$H$42,'Quiz 1'!$A$2:$A$42,$A30) -> 6.6666667 | C30: =_xlfn.MAXIFS('Quiz 2'!$H$2:$H$37,'Quiz 2'!$A$2:$A$37,$A30) -> 3.3333333 | D30: =_xlfn.MAXIFS('Quiz 3'!$H$2:$H$35,'Quiz 3'!$A$2:$A$35,$A30) -> 10 | E30: =_xlfn.MAXIFS('Quiz 4'!$H$2:$H$37,'Quiz 4'!$A$2:$A$37,$A30) -> 3.3333333 | F30: =SUMIF(Midterm!$A$2:$A$40,$A30,Midterm!$C$2:$C$40) -> 6.5 | G30: =SUM(B30:E30)*7.5% -> 1.75 | H30: =F30*20% -> 1.3 | I30: =G30+H30 -> 3.05 | J30: =I30/50% -> 6.1 | L30: =IF(ISNUMBER(K30),I30+K30*50%,"") | M30: =IF(ISNUMBER(K30),"Complete","Other instructor pending")&"" -> Other instructor pending
A31: 230 | B31: =_xlfn.MAXIFS('Quiz 1'!$H$2:$H$42,'Quiz 1'!$A$2:$A$42,$A31) -> 6.6666667 | C31: =_xlfn.MAXIFS('Quiz 2'!$H$2:$H$37,'Quiz 2'!$A$2:$A$37,$A31) -> 6.6666667 | D31: =_xlfn.MAXIFS('Quiz 3'!$H$2:$H$35,'Quiz 3'!$A$2:$A$35,$A31) -> 10 | E31: =_xlfn.MAXIFS('Quiz 4'!$H$2:$H$37,'Quiz 4'!$A$2:$A$37,$A31) -> 3.3333333 | F31: =SUMIF(Midterm!$A$2:$A$40,$A31,Midterm!$C$2:$C$40) -> 8 | G31: =SUM(B31:E31)*7.5% -> 2 | H31: =F31*20% -> 1.6 | I31: =G31+H31 -> 3.6 | J31: =I31/50% -> 7.2 | L31: =IF(ISNUMBER(K31),I31+K31*50%,"") | M31: =IF(ISNUMBER(K31),"Complete","Other instructor pending")&"" -> Other instructor pending
A32: 232 | B32: =_xlfn.MAXIFS('Quiz 1'!$H$2:$H$42,'Quiz 1'!$A$2:$A$42,$A32) -> 10 | C32: =_xlfn.MAXIFS('Quiz 2'!$H$2:$H$37,'Quiz 2'!$A$2:$A$37,$A32) -> 6.6666667 | D32: =_xlfn.MAXIFS('Quiz 3'!$H$2:$H$35,'Quiz 3'!$A$2:$A$35,$A32) -> 6.6666667 | E32: =_xlfn.MAXIFS('Quiz 4'!$H$2:$H$37,'Quiz 4'!$A$2:$A$37,$A32) -> 3.3333333 | F32: =SUMIF(Midterm!$A$2:$A$40,$A32,Midterm!$C$2:$C$40) -> 7 | G32: =SUM(B32:E32)*7.5% -> 2 | H32: =F32*20% -> 1.4 | I32: =G32+H32 -> 3.4 | J32: =I32/50% -> 6.8 | L32: =IF(ISNUMBER(K32),I32+K32*50%,"") | M32: =IF(ISNUMBER(K32),"Complete","Other instructor pending")&"" -> Other instructor pending
A33: 233 | B33: =_xlfn.MAXIFS('Quiz 1'!$H$2:$H$42,'Quiz 1'!$A$2:$A$42,$A33) -> 10 | C33: =_xlfn.MAXIFS('Quiz 2'!$H$2:$H$37,'Quiz 2'!$A$2:$A$37,$A33) -> 6.6666667 | D33: =_xlfn.MAXIFS('Quiz 3'!$H$2:$H$35,'Quiz 3'!$A$2:$A$35,$A33) -> 6.6666667 | E33: =_xlfn.MAXIFS('Quiz 4'!$H$2:$H$37,'Quiz 4'!$A$2:$A$37,$A33) -> 3.3333333 | F33: =SUMIF(Midterm!$A$2:$A$40,$A33,Midterm!$C$2:$C$40) -> 7.5 | G33: =SUM(B33:E33)*7.5% -> 2 | H33: =F33*20% -> 1.5 | I33: =G33+H33 -> 3.5 | J33: =I33/50% -> 7 | L33: =IF(ISNUMBER(K33),I33+K33*50%,"") | M33: =IF(ISNUMBER(K33),"Complete","Other instructor pending")&"" -> Other instructor pending
A34: 234 | B34: =_xlfn.MAXIFS('Quiz 1'!$H$2:$H$42,'Quiz 1'!$A$2:$A$42,$A34) -> 0 | C34: =_xlfn.MAXIFS('Quiz 2'!$H$2:$H$37,'Quiz 2'!$A$2:$A$37,$A34) -> 6.6666667 | D34: =_xlfn.MAXIFS('Quiz 3'!$H$2:$H$35,'Quiz 3'!$A$2:$A$35,$A34) -> 0 | E34: =_xlfn.MAXIFS('Quiz 4'!$H$2:$H$37,'Quiz 4'!$A$2:$A$37,$A34) -> 6.6666667 | F34: =SUMIF(Midterm!$A$2:$A$40,$A34,Midterm!$C$2:$C$40) -> 4.5 | G34: =SUM(B34:E34)*7.5% -> 1 | H34: =F34*20% -> 0.9 | I34: =G34+H34 -> 1.9 | J34: =I34/50% -> 3.8 | L34: =IF(ISNUMBER(K34),I34+K34*50%,"") | M34: =IF(ISNUMBER(K34),"Complete","Other instructor pending")&"; no record: Quiz 1, Quiz 3" -> Other instructor pending; no record: Quiz 1, Quiz 3
A35: 235 | B35: =_xlfn.MAXIFS('Quiz 1'!$H$2:$H$42,'Quiz 1'!$A$2:$A$42,$A35) -> 0 | C35: =_xlfn.MAXIFS('Quiz 2'!$H$2:$H$37,'Quiz 2'!$A$2:$A$37,$A35) -> 0 | D35: =_xlfn.MAXIFS('Quiz 3'!$H$2:$H$35,'Quiz 3'!$A$2:$A$35,$A35) -> 6.6666667 | E35: =_xlfn.MAXIFS('Quiz 4'!$H$2:$H$37,'Quiz 4'!$A$2:$A$37,$A35) -> 3.3333333 | F35: =SUMIF(Midterm!$A$2:$A$40,$A35,Midterm!$C$2:$C$40) -> 6 | G35: =SUM(B35:E35)*7.5% -> 0.75 | H35: =F35*20% -> 1.2 | I35: =G35+H35 -> 1.95 | J35: =I35/50% -> 3.9 | L35: =IF(ISNUMBER(K35),I35+K35*50%,"") | M35: =IF(ISNUMBER(K35),"Complete","Other instructor pending")&"; no record: Quiz 1" -> Other instructor pending; no record: Quiz 1
A36: 236 | B36: =_xlfn.MAXIFS('Quiz 1'!$H$2:$H$42,'Quiz 1'!$A$2:$A$42,$A36) -> 6.6666667 | C36: =_xlfn.MAXIFS('Quiz 2'!$H$2:$H$37,'Quiz 2'!$A$2:$A$37,$A36) -> 0 | D36: =_xlfn.MAXIFS('Quiz 3'!$H$2:$H$35,'Quiz 3'!$A$2:$A$35,$A36) -> 6.6666667 | E36: =_xlfn.MAXIFS('Quiz 4'!$H$2:$H$37,'Quiz 4'!$A$2:$A$37,$A36) -> 3.3333333 | F36: =SUMIF(Midterm!$A$2:$A$40,$A36,Midterm!$C$2:$C$40) -> 5 | G36: =SUM(B36:E36)*7.5% -> 1.25 | H36: =F36*20% -> 1 | I36: =G36+H36 -> 2.25 | J36: =I36/50% -> 4.5 | L36: =IF(ISNUMBER(K36),I36+K36*50%,"") | M36: =IF(ISNUMBER(K36),"Complete","Other instructor pending")&"; no record: Quiz 2" -> Other instructor pending; no record: Quiz 2
A37: 237 | B37: =_xlfn.MAXIFS('Quiz 1'!$H$2:$H$42,'Quiz 1'!$A$2:$A$42,$A37) -> 0 | C37: =_xlfn.MAXIFS('Quiz 2'!$H$2:$H$37,'Quiz 2'!$A$2:$A$37,$A37) -> 0 | D37: =_xlfn.MAXIFS('Quiz 3'!$H$2:$H$35,'Quiz 3'!$A$2:$A$35,$A37) -> 0 | E37: =_xlfn.MAXIFS('Quiz 4'!$H$2:$H$37,'Quiz 4'!$A$2:$A$37,$A37) -> 0 | F37: =SUMIF(Midterm!$A$2:$A$40,$A37,Midterm!$C$2:$C$40) -> 5 | G37: =SUM(B37:E37)*7.5% -> 0 | H37: =F37*20% -> 1 | I37: =G37+H37 -> 1 | J37: =I37/50% -> 2 | L37: =IF(ISNUMBER(K37),I37+K37*50%,"") | M37: =IF(ISNUMBER(K37),"Complete","Other instructor pending")&"; no record: Quiz 1, Quiz 3, Quiz 4" -> Other instructor pending; no record: Quiz 1, Quiz 3, Quiz 4
A38: 238 | B38: =_xlfn.MAXIFS('Quiz 1'!$H$2:$H$42,'Quiz 1'!$A$2:$A$42,$A38) -> 10 | C38: =_xlfn.MAXIFS('Quiz 2'!$H$2:$H$37,'Quiz 2'!$A$2:$A$37,$A38) -> 10 | D38: =_xlfn.MAXIFS('Quiz 3'!$H$2:$H$35,'Quiz 3'!$A$2:$A$35,$A38) -> 10 | E38: =_xlfn.MAXIFS('Quiz 4'!$H$2:$H$37,'Quiz 4'!$A$2:$A$37,$A38) -> 3.3333333 | F38: =SUMIF(Midterm!$A$2:$A$40,$A38,Midterm!$C$2:$C$40) -> 10 | G38: =SUM(B38:E38)*7.5% -> 2.5 | H38: =F38*20% -> 2 | I38: =G38+H38 -> 4.5 | J38: =I38/50% -> 9 | L38: =IF(ISNUMBER(K38),I38+K38*50%,"") | M38: =IF(ISNUMBER(K38),"Complete","Other instructor pending")&"" -> Other instructor pending
A39: 239 | B39: =_xlfn.MAXIFS('Quiz 1'!$H$2:$H$42,'Quiz 1'!$A$2:$A$42,$A39) -> 6.6666667 | C39: =_xlfn.MAXIFS('Quiz 2'!$H$2:$H$37,'Quiz 2'!$A$2:$A$37,$A39) -> 3.3333333 | D39: =_xlfn.MAXIFS('Quiz 3'!$H$2:$H$35,'Quiz 3'!$A$2:$A$35,$A39) -> 3.3333333 | E39: =_xlfn.MAXIFS('Quiz 4'!$H$2:$H$37,'Quiz 4'!$A$2:$A$37,$A39) -> 0 | F39: =SUMIF(Midterm!$A$2:$A$40,$A39,Midterm!$C$2:$C$40) -> 6 | G39: =SUM(B39:E39)*7.5% -> 1 | H39: =F39*20% -> 1.2 | I39: =G39+H39 -> 2.2 | J39: =I39/50% -> 4.4 | L39: =IF(ISNUMBER(K39),I39+K39*50%,"") | M39: =IF(ISNUMBER(K39),"Complete","Other instructor pending")&"" -> Other instructor pending
A40: 240 | B40: =_xlfn.MAXIFS('Quiz 1'!$H$2:$H$42,'Quiz 1'!$A$2:$A$42,$A40) -> 0 | C40: =_xlfn.MAXIFS('Quiz 2'!$H$2:$H$37,'Quiz 2'!$A$2:$A$37,$A40) -> 6.6666667 | D40: =_xlfn.MAXIFS('Quiz 3'!$H$2:$H$35,'Quiz 3'!$A$2:$A$35,$A40) -> 3.3333333 | E40: =_xlfn.MAXIFS('Quiz 4'!$H$2:$H$37,'Quiz 4'!$A$2:$A$37,$A40) -> 0 | F40: =SUMIF(Midterm!$A$2:$A$40,$A40,Midterm!$C$2:$C$40) -> 3 | G40: =SUM(B40:E40)*7.5% -> 0.75 | H40: =F40*20% -> 0.6 | I40: =G40+H40 -> 1.35 | J40: =I40/50% -> 2.7 | L40: =IF(ISNUMBER(K40),I40+K40*50%,"") | M40: =IF(ISNUMBER(K40),"Complete","Other instructor pending")&"; no record: Quiz 1" -> Other instructor pending; no record: Quiz 1
...
